Workbook

Sheet Model
A1: model | B1: 671B | C1: =match(B1,'DeepSeekV3 config'!C1:E1,0)+1 -> 2 | F1: Precision | G1: Element bits | H1: Block size | I1: Scale bits | J1: Bits/val
A2: vocab_size | B2: =vlookup(A2,'DeepSeekV3 config'!$B$1:$E$22,$C$1,0) -> 129280 | F2: fp4 | G2: 4 | H2: 16 | I2: 8 | J2: =(G2*H2+I2)/H2 -> 4.5
A3: dim | B3: =vlookup(A3,'DeepSeekV3 config'!$B$1:$E$22,$C$1,0) -> 7168 | F3: int8 | G3: 8 | H3: 32 | I3: 8 | J3: =(G3*H3+I3)/H3 -> 8.25
A4: q_lora_rank | B4: =vlookup(A4,'DeepSeekV3 config'!$B$1:$E$22,$C$1,0) -> 1536 | F4: fp8 | G4: 8 | H4: 32 | I4: 0 | J4: =(G4*H4+I4)/H4 -> 8
A5: n_heads | B5: =vlookup(A5,'DeepSeekV3 config'!$B$1:$E$22,$C$1,0) -> 128 | F5: bf16 | G5: 16 | H5: 1 | I5: 0 | J5: =(G5*H5+I5)/H5 -> 16
A6: qk_head_dim | B6: =vlookup(A6,'DeepSeekV3 config'!$B$1:$E$22,$C$1,0) -> 192
A7: qk_rope_head_dim | B7: =vlookup(A7,'DeepSeekV3 config'!$B$1:$E$22,$C$1,0) -> 64
A8: kv_lora_rank | B8: =vlookup(A8,'DeepSeekV3 config'!$B$1:$E$22,$C$1,0) -> 512
A9: v_head_dim | B9: =vlookup(A9,'DeepSeekV3 config'!$B$1:$E$22,$C$1,0) -> 128
A10: inter_dim | B10: =vlookup(A10,'DeepSeekV3 config'!$B$1:$E$22,$C$1,0) -> 18432
A11: moe_inter_dim | B11: =vlookup(A11,'DeepSeekV3 config'!$B$1:$E$22,$C$1,0) -> 2048
A12: n_routed_experts | B12: =vlookup(A12,'DeepSeekV3 config'!$B$1:$E$22,$C$1,0) -> 256
A13: n_shared_experts | B13: =vlookup(A13,'DeepSeekV3 config'!$B$1:$E$22,$C$1,0) -> 1
A14: n_activated_experts | B14: =vlookup(A14,'DeepSeekV3 config'!$B$1:$E$22,$C$1,0) -> 8
A15: n_layers | B15: =vlookup(A15,'DeepSeekV3 config'!$B$1:$E$22,$C$1,0) -> 61
A16: n_dense_layers | B16: =vlookup(A16,'DeepSeekV3 config'!$B$1:$E$22,$C$1,0) -> 3
A18: additional
A19: seq_len | B19: 1000
A20: batch_size | B20: 1
E22: batch_size=1 | G22: ="batch_size=" & B20 -> batch_size=1
C23: format | D23: N weights | E23: Ops | F23: N Activations | G23: Ops | H23: N Activations | I23: Weights MB | J23: Activ MB
A24: Vocab | B24: embed_tokens | C24: bf16 | D24: =B2*B3 -> 926679040 | E24: =B3 -> 7168 | F24: =B3 -> 7168 | G24: =E24*$B$20 -> 7168 | H24: =F24*$B$20 -> 7168 | I24: =vlookup(C24, $F$1:$J$5, 5, 0)*D24/8/2^20 -> 1767.5 | J24: =vlookup(C24, $F$1:$J$5, 5, 0)*H24/8/2^20 -> 0.013671875
A25: Vocab | B25: RoPE | C25: bf16 | E25: =2*F24 -> 14336 | F25: =F24 -> 7168 | G25: =E25*$B$20 -> 14336 | H25: =F25*$B$20 -> 7168 | I25: =vlookup(C25, $F$1:$J$5, 5, 0)*D25/8/2^20 -> 0 | J25: =vlookup(C25, $F$1:$J$5, 5, 0)*H25/8/2^20 -> 0.013671875
A26: MLA | B26: input_layernorm | C26: fp8 | E26: =3*(F25+1) -> 21507 | F26: =F25 -> 7168 | G26: =E26*$B$20 -> 21507 | H26: =F26*$B$20 -> 7168 | I26: =vlookup(C26, $F$1:$J$5, 5, 0)*D26/8/2^20 -> 0 | J26: =vlookup(C26, $F$1:$J$5, 5, 0)*H26/8/2^20 -> 0.0068359375
A27: MLA | B27: q_down_proj | C27: fp8 | D27: =B3*B4 -> 11010048 | E27: =D27*2 -> 22020096 | F27: =B4 -> 1536 | G27: =E27*$B$20 -> 22020096 | H27: =F27*$B$20 -> 1536 | I27: =vlookup(C27, $F$1:$J$5, 5, 0)*D27/8/2^20 -> 10.5 | J27: =vlookup(C27, $F$1:$J$5, 5, 0)*H27/8/2^20 -> 0.0014648438
A28: MLA | B28: q_down_layernorm | C28: fp8 | E28: =3*(F27+1) -> 4611 | F28: =F27 -> 1536 | G28: =E28*$B$20 -> 4611 | H28: =F28*$B$20 -> 1536 | I28: =vlookup(C28, $F$1:$J$5, 5, 0)*D28/8/2^20 -> 0 | J28: =vlookup(C28, $F$1:$J$5, 5, 0)*H28/8/2^20 -> 0.0014648438
A29: MLA | B29: q_up_proj | C29: fp8 | D29: =B4*B5*B6 -> 37748736 | E29: =D29*2 -> 75497472 | F29: =B5*B6 -> 24576 | G29: =E29*$B$20 -> 75497472 | H29: =F29*$B$20 -> 24576 | I29: =vlookup(C29, $F$1:$J$5, 5, 0)*D29/8/2^20 -> 36 | J29: =vlookup(C29, $F$1:$J$5, 5, 0)*H29/8/2^20 -> 0.0234375
A30: MLA | B30: kv_down_proj (+RoPE) | C30: fp8 | D30: =B3*(B7+B8) -> 4128768 | E30: =D30*2 -> 8257536 | F30: =B7+B8 -> 576 | G30: =E30*$B$20 -> 8257536 | H30: =F30*$B$20 -> 576 | I30: =vlookup(C30, $F$1:$J$5, 5, 0)*D30/8/2^20 -> 3.9375 | J30: =vlookup(C30, $F$1:$J$5, 5, 0)*H30/8/2^20 -> 0.00054931641
A31: MLA | B31: kv_down_layernorm | C31: fp8 | E31: =3*(F30+1) -> 1731 | F31: =F30 -> 576 | G31: =E31*$B$20 -> 1731 | H31: =F31*$B$20 -> 576 | I31: =vlookup(C31, $F$1:$J$5, 5, 0)*D31/8/2^20 -> 0 | J31: =vlookup(C31, $F$1:$J$5, 5, 0)*H31/8/2^20 -> 0.00054931641
A32: MLA | B32: Load K cache (+RoPE) | C32: fp8 | F32: =B19*(B8+B7) -> 576000 | G32: =E32*$B$20 -> 0 | H32: =F32*$B$20 -> 576000 | I32: =vlookup(C32, $F$1:$J$5, 5, 0)*D32/8/2^20 -> 0 | J32: =vlookup(C32, $F$1:$J$5, 5, 0)*H32/8/2^20 -> 0.54931641
A33: MLA | B33: Load V cache | C33: fp8 | F33: =B19*B8 -> 512000 | G33: =E33*$B$20 -> 0 | H33: =F33*$B$20 -> 512000 | I33: =vlookup(C33, $F$1:$J$5, 5, 0)*D33/8/2^20 -> 0 | J33: =vlookup(C33, $F$1:$J$5, 5, 0)*H33/8/2^20 -> 0.48828125
A34: MLA | B34: kv_up_proj | C34: fp8 | D34: =B8*B5*(B6+B9-B7) -> 16777216 | E34: =D34*2 -> 33554432 | F34: =B5*(B6+B9-B7) -> 32768 | G34: =E34*$B$20 -> 33554432 | H34: =F34*$B$20 -> 32768 | I34: =vlookup(C34, $F$1:$J$5, 5, 0)*D34/8/2^20 -> 16 | J34: =vlookup(C34, $F$1:$J$5, 5, 0)*H34/8/2^20 -> 0.03125
A35: MLA | B35: QK | C35: fp8 | E35: =B5*F32*2 -> 147456000 | F35: =B19*B5 -> 128000 | G35: =E35*$B$20 -> 147456000 | H35: =F35*$B$20 -> 128000 | I35: =vlookup(C35, $F$1:$J$5, 5, 0)*D35/8/2^20 -> 0 | J35: =vlookup(C35, $F$1:$J$5, 5, 0)*H35/8/2^20 -> 0.12207031
A36: MLA | B36: Scale + softmax (P) | C36: fp8 | E36: =B5*(8*B19+1) -> 1024128 | F36: =F35 -> 128000 | G36: =E36*$B$20 -> 1024128 | H36: =F36*$B$20 -> 128000 | I36: =vlookup(C36, $F$1:$J$5, 5, 0)*D36/8/2^20 -> 0 | J36: =vlookup(C36, $F$1:$J$5, 5, 0)*H36/8/2^20 -> 0.12207031
A37: MLA | B37: PV | C37: fp8 | E37: =2*F33*B5 -> 131072000 | F37: =B5*B9 -> 16384 | G37: =E37*$B$20 -> 131072000 | H37: =F37*$B$20 -> 16384 | I37: =vlookup(C37, $F$1:$J$5, 5, 0)*D37/8/2^20 -> 0 | J37: =vlookup(C37, $F$1:$J$5, 5, 0)*H37/8/2^20 -> 0.015625
A38: MLA | B38: o_proj | C38: fp8 | D38: =B5*B9*B3 -> 117440512 | E38: =D38*2 -> 234881024 | F38: =B3 -> 7168 | G38: =E38*$B$20 -> 234881024 | H38: =F38*$B$20 -> 7168 | I38: =vlookup(C38, $F$1:$J$5, 5, 0)*D38/8/2^20 -> 112 | J38: =vlookup(C38, $F$1:$J$5, 5, 0)*H38/8/2^20 -> 0.0068359375
A39: MLA | B39: post_attention_layernorm | C39: fp8 | E39: =3*(F38+1) -> 21507 | F39: =F38 -> 7168 | G39: =E39*$B$20 -> 21507 | H39: =F39*$B$20 -> 7168 | I39: =vlookup(C39, $F$1:$J$5, 5, 0)*D39/8/2^20 -> 0 | J39: =vlookup(C39, $F$1:$J$5, 5, 0)*H39/8/2^20 -> 0.0068359375
A40: MLP | B40: gate_proj | C40: fp8 | D40: =B3*B10 -> 132120576 | E40: =D40*2 -> 264241152 | F40: =B10 -> 18432 | G40: =E40*$B$20 -> 264241152 | H40: =F40*$B$20 -> 18432 | I40: =vlookup(C40, $F$1:$J$5, 5, 0)*D40/8/2^20 -> 126 | J40: =vlookup(C40, $F$1:$J$5, 5, 0)*H40/8/2^20 -> 0.017578125
A41: MLP | B41: up_proj | C41: fp8 | D41: =D40 -> 132120576 | E41: =D41*2 -> 264241152 | F41: =B10 -> 18432 | G41: =E41*$B$20 -> 264241152 | H41: =F41*$B$20 -> 18432 | I41: =vlookup(C41, $F$1:$J$5, 5, 0)*D41/8/2^20 -> 126 | J41: =vlookup(C41, $F$1:$J$5, 5, 0)*H41/8/2^20 -> 0.017578125
A42: MLP | B42: act_fn | C42: fp8 | E42: =(8+1)*F41 -> 165888 | F42: =F41 -> 18432 | G42: =E42*$B$20 -> 165888 | H42: =F42*$B$20 -> 18432 | I42: =vlookup(C42, $F$1:$J$5, 5, 0)*D42/8/2^20 -> 0 | J42: =vlookup(C42, $F$1:$J$5, 5, 0)*H42/8/2^20 -> 0.017578125
...

Sheet DeepSeekV3 config
B1: Model | C1: 671B | D1: 236B | E1: 16B
B2: Config | C2: Config | D2: Config | E2: Config
A3: V | B3: vocab_size | C3: 129280 | D3: 102400 | E3: 102400
A4: d | B4: dim | C4: 7168 | D4: 5120 | E4: 2048
B5: inter_dim | C5: 18432 | D5: 12288 | E5: 10944
B6: moe_inter_dim | C6: 2048 | D6: 1536 | E6: 1408
B7: n_layers | C7: 61 | D7: 60 | E7: 27
B8: n_dense_layers | C8: 3 | D8: 1 | E8: 1
B9: n_heads | C9: 128 | D9: 128 | E9: 16
B10: n_routed_experts | C10: 256 | D10: 160 | E10: 64
B11: n_shared_experts | C11: 1 | D11: 2 | E11: 2
B12: n_activated_experts | C12: 8 | D12: 6 | E12: 6
B13: n_expert_groups | C13: 8 | D13: 8
B14: n_limited_groups | C14: 4 | D14: 3
B15: route_scale | C15: 2.5 | D15: 16 | E15: 1
B16: score_func | C16: sigmoid
B17: q_lora_rank | C17: 1536 | D17: 1536 | E17: 0
A18: d_c | B18: kv_lora_rank | C18: 512 | D18: 512 | E18: 512
A19: d_h | B19: qk_nope_head_dim | C19: 128 | D19: 128 | E19: 128
B20: qk_rope_head_dim | C20: 64 | D20: 64 | E20: 64
B21: qk_head_dim | C21: =C19+C20 -> 192 | D21: =D19+D20 -> 192 | E21: 192
B22: v_head_dim | C22: 128 | D22: 128 | E22: 128

Sheet Nvidia
B1: Prefill | C1: Decode | F1: =F3*F12*F13 -> 320 | G1: =G3*G12*G13 -> 720 | H1: =H3*H12*H13 -> 9599.04 | I1: =I3*I12*I13 -> 1080 | J1: =J3*J12*J13 -> 2399.76 | K1: =K3*K12*K13 -> 9599.04 | L1: =L3*L12*L13 -> 14400 | M1: =M3*M12*M13 -> 2880
A2: Per package | B2: NVL72 | C2: NVL576 | D2: H100 | E2: H200 | F2: B200 | G2: NVL72 | H2: DRAM unicorn | I2: NVL72 Ultra | J2: NVL144 | K2: NVL576 | L2: OLD NVL576 | M2: Rubin CPX | P2: Reverse Jensen
A3: fp4 | B3: =offset($B$2, row($B1), match($B$2,$D$2:$M$2,0)+1) -> 10 | C3: =offset($C$2, row($C1), match($C$2,$D$2:$M$2,0)) -> 66.66 | F3: 10 | G3: =F3 -> 10 | H3: =K3 -> 66.66 | I3: 15 | J3: 33.33 | K3: =J3*2 -> 66.66 | L3: 100 | M3: 20 | N3: PFLOPS | P3: TPS/MW | Q3: =5.8*10^6 -> 5800000 | R3: <-- from curve
A4: fp8 | B4: =offset($B$2, row($B2), match($B$2,$D$2:$M$2,0)+1) -> 5 | C4: =offset($C$2, row($C2), match($C$2,$D$2:$M$2,0)) -> 22.22 | D4: 3.96 | E4: 3.96 | F4: =F3/2 -> 5 | G4: =F4 -> 5 | H4: =H3/3 -> 22.22 | I4: =F4*2 -> 10 | J4: =J3/3 -> 11.11 | K4: =J4*2 -> 22.22 | L4: =L3/2 -> 50 | M4: =M3/2 -> 10 | N4: PFLOPS | P4: tps/user | Q4: 220 | R4: <-- from curve
A5: bf16 | B5: =offset($B$2, row($B3), match($B$2,$D$2:$M$2,0)+1) -> 2.5 | C5: =offset($C$2, row($C3), match($C$2,$D$2:$M$2,0)) -> 11.11 | D5: 1.98 | E5: 1.98 | F5: =F4/2 -> 2.5 | G5: =F5 -> 2.5 | H5: =H4/2 -> 11.11 | I5: =F5*2 -> 5 | J5: =J4/2 -> 5.555 | K5: =K4/2 -> 11.11 | L5: =L4/2 -> 25 | M5: =M4/2 -> 5 | N5: PFLOPS | P5: bs | Q5: 128 | R5: <-- from curve
A6: int4 | B6: =offset($B$2, row($B4), match($B$2,$D$2:$M$2,0)+1) | C6: =offset($C$2, row($C4), match($C$2,$D$2:$M$2,0)) | N6: POPS | P6: OS time | Q6: =1000/Q4 -> 4.5454545 | R6: match TPS/user first
A7: int8 | B7: =offset($B$2, row($B5), match($B$2,$D$2:$M$2,0)+1) -> 5 | C7: =offset($C$2, row($C5), match($C$2,$D$2:$M$2,0)) | D7: 3.96 | E7: 3.96 | F7: =F4 -> 5 | G7: =F7 -> 5 | I7: =23/I12 -> 0.31944444 | N7: POPS | P7: tok/sec/system | Q7: =3000/(Q6*1.1)*Q5 -> 76800 | R7: then use whole seq for throughput
A8: Effective kW | B8: =offset($B$2, row($B6), match($B$2,$D$2:$M$2,0)+1) -> 1.6666667 | C8: =offset($C$2, row($C6), match($C$2,$D$2:$M$2,0)) -> 4.1666667 | D8: =D17/(D12*D13) -> 1.53125 | E8: =E17/(E12*E13) -> 1.53125 | F8: =F17/(F12*F13) -> 2.125 | G8: =G17/(G12*G13) -> 1.6666667 | H8: =H17/(H12*H13) -> 4.1666667 | I8: =I17/(I12*I13) -> 1.8055556 | J8: =J17/(J12*J13) -> 2.0833333 | K8: =K17/(K12*K13) -> 4.1666667 | ... M8: =M17/(M12*M13) -> 1.1111111 | P8: kW/system | Q8: =1000/Q3*Q7 -> 13.241379 | R8: implied system power
A9: HBM size | B9: =offset($B$2, row($B7), match($B$2,$D$2:$M$2,0)+1) -> 196608 | C9: =offset($C$2, row($C7), match($C$2,$D$2:$M$2,0)) -> 1048576 | D9: 81920 | E9: 144384 | F9: 196608 | G9: =F9 -> 196608 | H9: =K9 -> 1048576 | I9: =288*1024 -> 294912 | J9: =288*1024 -> 294912 | K9: =1024*1024 -> 1048576 | L9: =1024*1024 -> 1048576 | M9: =128*1024 -> 131072 | N9: MB | P9: 8 | Q9: =Q8/P9 -> 1.6551724 | R9: guess how many GPUs
A10: HBM BW | B10: =offset($B$2, row($B8), match($B$2,$D$2:$M$2,0)+1) -> 8192 | C10: =offset($C$2, row($C8), match($C$2,$D$2:$M$2,0)) * C26 -> 41984 | D10: =3.35*2^10 -> 3430.4 | E10: =4.8*2^10 -> 4915.2 | F10: =8*2^10 -> 8192 | G10: =8*2^10 -> 8192 | H10: =900*2^10 -> 921600 | I10: =8*2^10 -> 8192 | J10: =13*1024 -> 13312 | K10: =41*1024 -> 41984 | L10: =32*1024 -> 32768 | M10: =2*1024 -> 2048 | N10: GB/s
B11: =offset($B$2, row($B9), match($B$2,$D$2:$M$2,0)+1) | C11: =offset($C$2, row($C9), match($C$2,$D$2:$M$2,0))
A12: Packages/chassis | B12: =offset($B$2, row($B10), match($B$2,$D$2:$M$2,0)+1) -> 72 | C12: =offset($C$2, row($C10), match($C$2,$D$2:$M$2,0)) -> 144 | D12: 8 | E12: 8 | F12: 8 | G12: 72 | H12: =K12 -> 144 | I12: 72 | J12: 72 | K12: 144 | L12: 144 | M12: 8
A13: Chassis/rack | B13: =offset($B$2, row($B11), match($B$2,$D$2:$M$2,0)+1) -> 1 | C13: =offset($C$2, row($C11), match($C$2,$D$2:$M$2,0)) -> 1 | D13: 4 | E13: 4 | F13: 4 | G13: 1 | H13: =K13 -> 1 | I13: 1 | J13: 1 | K13: 1 | L13: 1 | M13: 18 | P13: fp4
A14: Intra Chassis BW | B14: =offset($B$2, row($B12), match($B$2,$D$2:$M$2,0)+1) -> 900 | C14: =offset($C$2, row($C12), match($C$2,$D$2:$M$2,0)) -> 1800 | D14: 450 | E14: 450 | F14: 900 | G14: 900 | H14: =K14 -> 1800 | I14: 900 | J14: =I14*2 -> 1800 | K14: =J14 -> 1800 | L14: =K14 -> 1800 | M14: 128 | N14: GB/s | P14: fp4/fp8
A15: BTW Chassis BW | B15: =offset($B$2, row($B13), match($B$2,$D$2:$M$2,0)+1) -> 900 | C15: =offset($C$2, row($C13), match($C$2,$D$2:$M$2,0)) -> 1800 | D15: 400 | E15: 400 | F15: 400 | G15: 900 | H15: =K15 -> 1800 | I15: 900 | J15: =I15*2 -> 1800 | K15: =J15 -> 1800 | L15: =K15 -> 1800 | M15: 128 | N15: GB/s | P15: Blog
A16: NV Link setup latency | B16: =offset($B$2, row($B14), match($B$2,$D$2:$M$2,0)+1) -> 0.2 | C16: =offset($C$2, row($C14), match($C$2,$D$2:$M$2,0)) -> 0.2 | D16: 0.8 | E16: 0.8 | F16: 0.2 | G16: 0.2 | H16: 0.2 | I16: 0.2 | J16: 0.2 | K16: =J16 -> 0.2 | L16: =K16 -> 0.2 | M16: 0.2 | N16: micros
A17: kW/rack | B17: =offset($B$2, row($B15), match($B$2,$D$2:$M$2,0)+1) -> 120 | C17: =offset($C$2, row($C15), match($C$2,$D$2:$M$2,0)) -> 600 | D17: ='TCO model'!C17 -> 49 | E17: ='TCO model'!D17 -> 49 | F17: ='TCO model'!E17 -> 68 | G17: ='TCO model'!F17 -> 120 | H17: =K17 -> 600 | I17: ='TCO model'!G17 -> 130 | J17: ='TCO model'!H17 -> 150 | K17: ='TCO model'!I17 -> 600 | L17: ='TCO model'!J17 -> 69.2 | M17: 160
A18: TCO $/sec | B18: =offset($B$2, row($B16), match($B$2,$D$2:$M$2,0)+1) -> 0.040149713 | C18: =offset($C$2, row($C16), match($C$2,$D$2:$M$2,0)) -> 0.17427335 | D18: ='TCO model'!C21 -> 0.019518542 | E18: ='TCO model'!D21 -> 0.02057755 | F18: ='TCO model'!E21 -> 0.026563935 | G18: ='TCO model'!$F$21 -> 0.040149713 | H18: =K18 -> 0.17427335 | I18: ='TCO model'!$G$21 -> 0.046143044 | J18: ='TCO model'!$H$21 -> 0.063424749 | K18: ='TCO model'!$I$21 -> 0.17427335 | L18: =K18 -> 0.17427335 | M18: =G18 -> 0.040149713
A20: MoE penallty | B20: 0.1 | C20: 0.2
A22: Deployment
A23: Sequence length | B23: 8000 | C23: 1000
A24: Batch size | B24: 1024 | C24: 1024
A25: KV load factor | C25: =1 + Model!B8/(Model!B8+Model!B7) * (1-E25) -> 1.4444444 | E25: =2^floor(log(70 / ((Model!$B$8+Model!$B$7)*vlookup($C$42, Model!$F$1:Model!$J$5, 5, 0)/8/1024), 2),1) / 128 -> 0.5 | F25: <-- % optimal tile size in MLA
A26: HBM efficiency | B26: =0.5 + 0.5 * min((B23*B24/1000)/128, 1) -> 1 | C26: =0.5 + 0.5 * min((C23*C24/1000)/128, 1) -> 1
A28: kernel launch | B28: 1.5 | C28: micros
A29: Kernel fusion | B29: 0.67 | E29: =sum(D34:D59) = sum(Model!D24:D50) -> TRUE
A30: Weight format | B30: fp4/fp8 | C30: https://github.com/NVIDIA/TensorRT-LLM/blob/main/docs/source/blogs/tech_blog/blog1_Pushing_Latency_Boundaries_Optimizing_DeepSeek-R1_Performance_on_NVIDIA_B200_GPUs.md#precision-strategy
E32: ="IN seq_len=" & B23 & ", batch_size=" & B24 -> IN seq_len=8000, batch_size=1024 | J32: ="OUT seq_len=" & C23 & ", batch_size=" & C24 -> OUT seq_len=1000, batch_size=1024
C33: format | D33: N weights | E33: P[FL]OPS | F33: Ops | G33: N Activations | H33: Weights MB | I33: Activ MB | K33: Ops | L33: N Activations | M33: Weights MB | N33: Activ MB
A34: Vocab | B34: embed_tokens | C34: =if($B$30="Blog", "bf16", if($B$30="fp4/fp8", "fp8", "fp4")) -> fp8 | D34: =Model!B2*Model!B3 -> 926679040 | E34: =vlookup(C34, $A$3:$B$7, 2, 0) -> 5 | F34: =Model!$B$3*$B$24 -> 7340032 | G34: =Model!$B$3*$B$24 -> 7340032 | H34: =vlookup($C34, Model!$F$1:Model!$J$5, 5, 0)*D34/8/2^20 -> 883.75 | I34: =vlookup($C34, Model!$F$1:Model!$J$5, 5, 0)*G34/8/2^20 -> 7 | J34: =vlookup(C34, $A$3:$C$7, 3, 0) -> 22.22 | K34: =Model!$B$3*$C$24 -> 7340032 | L34: =Model!$B$3*$C$24 -> 7340032 | M34: =vlookup($C34, Model!$F$1:Model!$J$5, 5, 0)*$D34/8/2^20 -> 883.75 | N34: =vlookup($C34, Model!$F$1:Model!$J$5, 5, 0)*L34/8/2^20 -> 7
A35: Vocab | B35: RoPE | C35: =if($B$30="Blog", "bf16", if($B$30="fp4/fp8", "fp8", "fp4")) -> fp8 | E35: =vlookup(C35, $A$3:$B$7, 2, 0) -> 5 | F35: =2*Model!$B$3*$B$24 -> 14680064 | G35: =Model!$B$3*$B$24 -> 7340032 | H35: =vlookup($C35, Model!$F$1:Model!$J$5, 5, 0)*D35/8/2^20 -> 0 | I35: =vlookup($C35, Model!$F$1:Model!$J$5, 5, 0)*G35/8/2^20 -> 7 | J35: =vlookup(C35, $A$3:$C$7, 3, 0) -> 22.22 | K35: =2*Model!$B$3*$C$24 -> 14680064 | L35: =Model!$B$3*$C$24 -> 7340032 | M35: =vlookup($C35, Model!$F$1:Model!$J$5, 5, 0)*$D35/8/2^20 -> 0 | N35: =vlookup($C35, Model!$F$1:Model!$J$5, 5, 0)*L35/8/2^20 -> 7
A36: MLA | B36: input_layernorm | C36: bf16 | E36: =vlookup(C36, $A$3:$B$7, 2, 0) -> 2.5 | F36: =3*(Model!$B$3+1)*$B$24 -> 22023168 | G36: =G35 -> 7340032 | H36: =vlookup($C36, Model!$F$1:Model!$J$5, 5, 0)*D36/8/2^20 -> 0 | I36: =vlookup($C36, Model!$F$1:Model!$J$5, 5, 0)*G36/8/2^20 -> 14 | J36: =vlookup(C36, $A$3:$C$7, 3, 0) -> 11.11 | K36: =3*(Model!$B$3+1)*$C$24 -> 22023168 | L36: =L35 -> 7340032 | M36: =vlookup($C36, Model!$F$1:Model!$J$5, 5, 0)*$D36/8/2^20 -> 0 | N36: =vlookup($C36, Model!$F$1:Model!$J$5, 5, 0)*L36/8/2^20 -> 14
A37: MLA | B37: q_down_proj | C37: =if($B$30="Blog", "bf16", if($B$30="fp4/fp8", "fp8", "fp4")) -> fp8 | D37: =Model!B3*Model!B4 -> 11010048 | E37: =vlookup(C37, $A$3:$B$7, 2, 0) -> 5 | F37: =$D$37*2*$B$24 -> 22548578304 | G37: =Model!$B$4*$B$24 -> 1572864 | H37: =vlookup($C37, Model!$F$1:Model!$J$5, 5, 0)*D37/8/2^20 -> 10.5 | I37: =vlookup($C37, Model!$F$1:Model!$J$5, 5, 0)*G37/8/2^20 -> 1.5 | J37: =vlookup(C37, $A$3:$C$7, 3, 0) -> 22.22 | K37: =$D$37*2*$C$24 -> 22548578304 | L37: =Model!$B$4*$C$24 -> 1572864 | M37: =vlookup($C37, Model!$F$1:Model!$J$5, 5, 0)*$D37/8/2^20 -> 10.5 | N37: =vlookup($C37, Model!$F$1:Model!$J$5, 5, 0)*L37/8/2^20 -> 1.5
A38: MLA | B38: q_down_layernorm | C38: bf16 | D38: 0 | E38: =vlookup(C38, $A$3:$B$7, 2, 0) -> 2.5 | F38: =3*(Model!$B$4+1)*$B$24 -> 4721664 | G38: =Model!$B$4*$B$24 -> 1572864 | H38: =vlookup($C38, Model!$F$1:Model!$J$5, 5, 0)*D38/8/2^20 -> 0 | I38: =vlookup($C38, Model!$F$1:Model!$J$5, 5, 0)*G38/8/2^20 -> 3 | J38: =vlookup(C38, $A$3:$C$7, 3, 0) -> 11.11 | K38: =3*(Model!$B$4+1)*$C$24 -> 4721664 | L38: =Model!$B$4*$C$24 -> 1572864 | M38: =vlookup($C38, Model!$F$1:Model!$J$5, 5, 0)*$D38/8/2^20 -> 0 | N38: =vlookup($C38, Model!$F$1:Model!$J$5, 5, 0)*L38/8/2^20 -> 3
A39: MLA | B39: q_up_proj | C39: =if($B$30="Blog", "bf16", if($B$30="fp4/fp8", "fp8", "fp4")) -> fp8 | D39: =Model!B4*Model!B5*Model!B6 -> 37748736 | E39: =vlookup(C39, $A$3:$B$7, 2, 0) -> 5 | F39: =$D$39*2*$B$24 -> 77309411328 | G39: =Model!$B$5*Model!$B$6*$B$24 -> 25165824 | H39: =vlookup($C39, Model!$F$1:Model!$J$5, 5, 0)*D39/8/2^20 -> 36 | I39: =vlookup($C39, Model!$F$1:Model!$J$5, 5, 0)*G39/8/2^20 -> 24 | J39: =vlookup(C39, $A$3:$C$7, 3, 0) -> 22.22 | K39: =$D$39*2*$C$24 -> 77309411328 | L39: =Model!$B$5*Model!$B$6*$C$24 -> 25165824 | M39: =vlookup($C39, Model!$F$1:Model!$J$5, 5, 0)*$D39/8/2^20 -> 36 | N39: =vlookup($C39, Model!$F$1:Model!$J$5, 5, 0)*L39/8/2^20 -> 24
A40: MLA | B40: kv_down_proj (+RoPE) | C40: =if($B$30="Blog", "bf16", if($B$30="fp4/fp8", "fp8", "fp4")) -> fp8 | D40: =Model!B3*(Model!B7+Model!B8) -> 4128768 | E40: =vlookup(C40, $A$3:$B$7, 2, 0) -> 5 | F40: =$D$40*2*$B$24 -> 8455716864 | G40: =(Model!$B$7+Model!$B$8)*$B$24 -> 589824 | H40: =vlookup($C40, Model!$F$1:Model!$J$5, 5, 0)*D40/8/2^20 -> 3.9375 | I40: =vlookup($C40, Model!$F$1:Model!$J$5, 5, 0)*G40/8/2^20 -> 0.5625 | J40: =vlookup(C40, $A$3:$C$7, 3, 0) -> 22.22 | K40: =$D$40*2*$C$24 -> 8455716864 | L40: =(Model!$B$7+Model!$B$8)*$C$24 -> 589824 | M40: =vlookup($C40, Model!$F$1:Model!$J$5, 5, 0)*$D40/8/2^20 -> 3.9375 | N40: =vlookup($C40, Model!$F$1:Model!$J$5, 5, 0)*L40/8/2^20 -> 0.5625
A41: MLA | B41: kv_down_layernorm | C41: bf16 | E41: =vlookup(C41, $A$3:$B$7, 2, 0) -> 2.5 | F41: =3*((Model!$B$7+Model!$B$8)+1)*$B$24 -> 1772544 | G41: =(Model!$B$7+Model!$B$8)*$B$24 -> 589824 | H41: =vlookup($C41, Model!$F$1:Model!$J$5, 5, 0)*D41/8/2^20 -> 0 | I41: =vlookup($C41, Model!$F$1:Model!$J$5, 5, 0)*G41/8/2^20 -> 1.125 | J41: =vlookup(C41, $A$3:$C$7, 3, 0) -> 11.11 | K41: =3*((Model!$B$7+Model!$B$8)+1)*$C$24 -> 1772544 | L41: =(Model!$B$7+Model!$B$8)*$C$24 -> 589824 | M41: =vlookup($C41, Model!$F$1:Model!$J$5, 5, 0)*$D41/8/2^20 -> 0 | N41: =vlookup($C41, Model!$F$1:Model!$J$5, 5, 0)*L41/8/2^20 -> 1.125
A42: MLA | B42: Latent KV (+RoPE) | C42: =if($B$30="Blog", "bf16", if($B$30="fp4/fp8", "fp8", "fp4")) -> fp8 | E42: =vlookup(C42, $A$3:$B$7, 2, 0) -> 5 | G42: =$B$23*(Model!$B$8+Model!$B$7)*$B$24 -> 4718592000 | H42: =vlookup($C42, Model!$F$1:Model!$J$5, 5, 0)*D42/8/2^20 -> 0 | I42: =vlookup($C42, Model!$F$1:Model!$J$5, 5, 0)*G42/8/2^20 -> 4500 | J42: =vlookup(C42, $A$3:$C$7, 3, 0) -> 22.22 | L42: =($B$23+$C$23)*(Model!$B$8+Model!$B$7)*$C$24 -> 5308416000 | M42: =vlookup($C42, Model!$F$1:Model!$J$5, 5, 0)*$D42/8/2^20 -> 0 | N42: =vlookup($C42, Model!$F$1:Model!$J$5, 5, 0)*L42/8/2^20 -> 5062.5
A43: MLA | B43: kv_up_proj | C43: =if($B$30="Blog", "bf16", if($B$30="fp4/fp8", "fp8", "fp4")) -> fp8 | D43: =Model!B8*Model!B5*(Model!B6+Model!B9-Model!B7) -> 16777216 | E43: =vlookup(C43, $A$3:$B$7, 2, 0) -> 5 | F43: =$D$43*2*$B$24 -> 34359738368 | G43: =Model!$B$5*(Model!$B$6+Model!$B$9-Model!$B$7)*$B$24 -> 33554432 | H43: =vlookup($C43, Model!$F$1:Model!$J$5, 5, 0)*D43/8/2^20 -> 16 | I43: =vlookup($C43, Model!$F$1:Model!$J$5, 5, 0)*G43/8/2^20 -> 32 | J43: =vlookup(C43, $A$3:$C$7, 3, 0) -> 22.22 | K43: =$D$43*2*$C$24 -> 34359738368 | L43: =Model!$B$5*(Model!$B$6+Model!$B$9-Model!$B$7)*$C$24 -> 33554432 | M43: =vlookup($C43, Model!$F$1:Model!$J$5, 5, 0)*$D43/8/2^20 -> 16 | N43: =vlookup($C43, Model!$F$1:Model!$J$5, 5, 0)*L43/8/2^20 -> 32
A44: MLA | B44: QK | C44: =if($B$30="Blog", "bf16", if($B$30="fp4/fp8", "fp8", "fp4")) -> fp8 | E44: =vlookup(C44, $A$3:$B$7, 2, 0) -> 5 | F44: =Model!$B$5*$B$23*(Model!$B$8+Model!$B$7)*$B$24*2 -> 1207959552000 | G44: =$B$23*Model!$B$5*$B$24 -> 1048576000 | H44: =vlookup($C44, Model!$F$1:Model!$J$5, 5, 0)*D44/8/2^20 -> 0 | I44: =vlookup($C44, Model!$F$1:Model!$J$5, 5, 0)*G44/8/2^20 -> 1000 | J44: =vlookup(C44, $A$3:$C$7, 3, 0) -> 22.22 | K44: =Model!$B$5*($B$23+$C$23)*(Model!$B$8+Model!$B$7)*$C$24*2 -> 1358954496000 | L44: =($B$23+$C$23)*Model!$B$5*$C$24 -> 1179648000 | M44: =vlookup($C44, Model!$F$1:Model!$J$5, 5, 0)*$D44/8/2^20 -> 0 | N44: =vlookup($C44, Model!$F$1:Model!$J$5, 5, 0)*L44/8/2^20 -> 1125
...

Sheet TCO model
B2: Unit | C2: H100 | D2: H200 | E2: B200 | F2: NVL72 | G2: NVL72 Ultra | H2: NVL144 | I2: NVL576 | J2: LPU v2 | K2: WSE-3 | L2: SN40L-16 | M2: Fractile?
A3: Capex
A4: Cost of building DC | B4: USD/rack | C4: 0 | D4: 0 | E4: 0 | F4: 0 | G4: 0 | H4: 0 | I4: 0 | J4: 0 | K4: 0 | L4: 0 | M4: 0
A5: Server Cost | B5: USD | C5: =380*4000 -> 1520000 | D5: =405*4000 -> 1620000 | E5: =515*4000 -> 2060000 | F5: =3*10^6 -> 3000000 | G5: =3.5*10^6 -> 3500000 | H5: =5*10^6 -> 5000000 | I5: =12.5*10^6 -> 12500000 | J5: =350*8000 -> 2800000 | K5: =3130*2000 -> 6260000 | L5: =800*1000 -> 800000 | M5: =3000000 -> 3000000
A6: Useful Life in Years | B6: Years | C6: 4 | D6: 4 | E6: 4 | F6: 4 | G6: 4 | H6: =F6 -> 4 | I6: =H6 -> 4 | J6: =I6 -> 4 | K6: =J6 -> 4 | L6: =K6 -> 4 | M6: =L6 -> 4
A7: Cost of Capital | B7: % | C7: 0.15 | D7: =C7 -> 0.15 | E7: =D7 -> 0.15 | F7: =E7 -> 0.15 | G7: =F7 -> 0.15 | H7: =G7 -> 0.15 | I7: =H7 -> 0.15 | J7: =I7 -> 0.15 | K7: =J7 -> 0.15 | ... M7: =L7 -> 0.15
A8: Total Capex per Month | B8: USD/m | C8: =PMT(C7/12,C6*12,-(C4+C5)) -> 42302.737 | D8: =PMT(D7/12,D6*12,-(D4+D5)) -> 45085.812 | E8: =PMT(E7/12,E6*12,-(E4+E5)) -> 57331.341 | F8: =PMT(F7/12,F6*12,-(F4+F5)) -> 83492.245 | G8: =PMT(G7/12,G6*12,-(G4+G5)) -> 97407.619 | H8: =PMT(H7/12,H6*12,-H5) -> 139153.74 | I8: =PMT(I7/12,I6*12,-I5) -> 347884.35 | J8: =PMT(J7/12,J6*12,-J5) -> 77926.095 | K8: =PMT(K7/12,K6*12,-K5) -> 174220.48 | L8: =PMT(L7/12,L6*12,-L5) -> 22264.599 | M8: =PMT(M7/12,M6*12,-M5) -> 83492.245
A10: Opex
A11: Electricity Cost | B11: USD/kWh | C11: 0.087 | D11: 0.087 | E11: 0.087 | F11: 0.087 | G11: 0.087 | H11: 0.087 | I11: 0.087 | J11: 0.087 | K11: 0.087 | L11: 0.087 | M11: 0.087
A12: Utilization Rate | B12: % | C12: 0.8 | D12: 0.8 | E12: 0.8 | F12: 0.8 | G12: 0.8 | H12: 0.8 | I12: 0.8 | J12: 0.8 | K12: 0.8 | L12: 0.8 | M12: 0.8
A13: Power Usage Effectiveness (PUE) | B13: Ratio | C13: 1.25 | D13: 1.25 | E13: 1.25 | F13: 1.25 | G13: 1.25 | H13: 1.25 | I13: 1.25 | J13: 1.25 | K13: 1.25 | L13: 1.25 | M13: 1.25
A14: Electricity Cost per kW per mth | B14: USD/kW/mth | C14: =C11*24*365/12*C13*C12 -> 63.51 | D14: =D11*24*365/12*D13*D12 -> 63.51 | E14: =E11*24*365/12*E13*E12 -> 63.51 | F14: =F11*24*365/12*F13*F12 -> 63.51 | G14: =G11*24*365/12*G13*G12 -> 63.51 | H14: =H11*24*365/12*H13*H12 -> 63.51 | I14: =I11*24*365/12*I13*I12 -> 63.51 | J14: =J11*24*365/12*J13*J12 -> 63.51 | ... M14: =M11*24*365/12*M13*M12 -> 63.51
A15: Colocation Cost | B15: USD/kW/mth | C15: =if(C4, 0, 120) -> 120 | D15: =if(D4, 0, 120) -> 120 | E15: =if(E4, 0, 120) -> 120 | F15: =if(F4, 0, 120) -> 120 | G15: =if(G4, 0, 120) -> 120 | H15: =if(H4, 0, 120) -> 120 | I15: =if(I4, 0, 120) -> 120 | J15: =if(J4, 0, 120) -> 120 | ... M15: =if(M4, 0, 120) -> 120
A16: Total Hosting Cost per kW per Month | B16: USD/kW/mth | C16: =C15+C14 -> 183.51 | D16: =D15+D14 -> 183.51 | E16: =E15+E14 -> 183.51 | F16: =F15+F14 -> 183.51 | G16: =G15+G14 -> 183.51 | H16: =H15+H14 -> 183.51 | I16: =I15+I14 -> 183.51 | J16: =J15+J14 -> 183.51 | ... M16: =M15+M14 -> 183.51
A17: Server Power Consumption | B17: kW | C17: 49 | D17: 49 | E17: 68 | F17: 120 | G17: 130 | H17: 150 | I17: 600 | J17: =4*17.3 -> 69.2 | K17: 50 | L17: 12 | M17: 120
A18: Total Opex per Month | B18: USD/mth | C18: =C17*C16 -> 8991.99 | D18: =D17*D16 -> 8991.99 | E18: =E17*E16 -> 12478.68 | F18: =F17*F16 -> 22021.2 | G18: =G17*G16 -> 23856.3 | H18: =H17*H16 -> 27526.5 | I18: =I17*I16 -> 110106 | J18: =J17*J16 -> 12698.892 | ... M18: =M17*M16 -> 22021.2
A20: Total Cost | B20: USD/m | C20: =C18+C8 -> 51294.727 | D20: =D18+D8 -> 54077.802 | E20: =E18+E8 -> 69810.021 | F20: =F18+F8 -> 105513.44 | G20: =G18+G8 -> 121263.92 | H20: =H18+H8 -> 166680.24 | I20: =I18+I8 -> 457990.35 | J20: =J18+J8 -> 90624.987 | ... M20: =M18+M8 -> 105513.44
A21: Total Cost | B21: USD/sec | C21: =C20/(365/12*24*3600) -> 0.019518542 | D21: =D20/(365/12*24*3600) -> 0.02057755 | E21: =E20/(365/12*24*3600) -> 0.026563935 | F21: =F20/(365/12*24*3600) -> 0.040149713 | G21: =G20/(365/12*24*3600) -> 0.046143044 | H21: =H20/(365/12*24*3600) -> 0.063424749 | I21: =I20/(365/12*24*3600) -> 0.17427335 | J21: =J20/(365/12*24*3600) -> 0.034484394 | ... M21: =M20/(365/12*24*3600) -> 0.040149713
A23: Capex % | C23: =C8/C20 -> 0.82469953 | D23: =D8/D20 -> 0.83372124 | E23: =E8/E20 -> 0.82124801 | F23: =F8/F20 -> 0.79129484 | G23: =G8/G20 -> 0.80326959 | H23: =H8/H20 -> 0.83485445 | I23: =I8/I20 -> 0.75958882 | J23: =J8/J20 -> 0.85987428 | ... M23: =M8/M20 -> 0.79129484
A24: Opex % | C24: =C18/C20 -> 0.17530047 | D24: =D18/D20 -> 0.16627876 | E24: =E18/E20 -> 0.17875199 | F24: =F18/F20 -> 0.20870516 | G24: =G18/G20 -> 0.19673041 | H24: =H18/H20 -> 0.16514555 | I24: =I18/I20 -> 0.24041118 | J24: =J18/J20 -> 0.14012572 | ... M24: =M18/M20 -> 0.20870516
B26: from inferenceMax | C26: 8k/1k | D26: 1k/1k
B27: kW/GPU | C27: 2.1 | D27: 2.1
B28: $/GPU/hr | C28: 2.21 | D28: 2.21 | F28: rack TCO
B29: TCO/Mtok | C29: 0.867 | D29: 2.093 | F29: =F20*12 -> 1266161.3 | G29: y
B30: tok/s/GPU | C30: 708.4 | D30: 293 | F30: =F29/365 -> 3468.9352 | G30: d
A31: =C30/(C27/1000) -> 337333.33 | B31: tok/s/MW | C31: 337337 | D31: 139649 | F31: =F30/24 -> 144.53897 | G31: h
A32: =C30*72 -> 51004.8 | B32: tok/s/rack | C32: =C31*(C27*72/1000) -> 51005.354 | D32: =D31*(D27*72/1000) -> 21114.929 | F32: =F31/60 -> 2.4089828 | G32: m
C33: =C32*3.6/1000 -> 183.61928 | D33: =D32*3.6/1000 -> 76.013744 | F33: =F32/60 -> 0.040149713 | G33: s
A35: =1000*C28/ (C30*3.6) -> 0.86658511 | B35: $/Mtok | C35: =C28*72/C33 -> 0.86657569 | D35: =D28*72/D33 -> 2.0933057 | F35: =F31/72 -> 2.0074856 | G35: $/GPU/hr
B38: From Jensen's plot
B39: kW/GPU | C39: 2.1
B40: $/GPU/hr | C40: 2.21
C42: Jensen (1k/2k) | D42: IMax (8k/1k) | E42: IMax (1k/1k)
B43: tok/s/MW | C43: 5800000 | D43: =C31 -> 337337 | E43: =D31 -> 139649
B44: tok/s/rack | C44: =C43*(C39*72/1000) -> 876960 | D44: =C32 -> 51005.354 | E44: =D32 -> 21114.929
C45: =C44*3.6/1000 -> 3157.056 | D45: =C33 -> 183.61928 | E45: =D33 -> 76.013744
E46: =D34
B47: $/Mtok | C47: =C40*72/C45 -> 0.050401387 | D47: =C35 -> 0.86657569 | E47: =D35 -> 2.0933057
C50: Jensen (1k/2k) | D50: IMax (8k/1k) | E50: IMax (1k/1k)
B51: tok/s/MW | C51: 5800000 | D51: 337337 | E51: 139649
...
